{
    "dataType": "CVE_RECORD",
    "dataVersion": "5.0",
    "cveMetadata": {
        "state": "PUBLISHED",
        "cveId": "CVE-2023-28859",
        "assignerOrgId": "8254265b-2729-46b6-b9e3-3dfca2d5bfca",
        "assignerShortName": "mitre",
        "dateUpdated": "2023-03-26T00:00:00",
        "dateReserved": "2023-03-26T00:00:00",
        "datePublished": "2023-03-26T00:00:00"
    },
    "containers": {
        "cna": {
            "providerMetadata": {
                "orgId": "8254265b-2729-46b6-b9e3-3dfca2d5bfca",
                "shortName": "mitre",
                "dateUpdated": "2023-03-26T00:00:00"
            },
            "descriptions": [
                {
                    "lang": "en",
                    "value": "redis-py through 4.5.3 leaves a connection open after canceling an async Redis command at an inopportune time (in the case of a non-pipeline operation), and can send response data to the client of an unrelated request. NOTE: this issue exists because of an incomplete fix for CVE-2023-28858."
                }
            ],
            "affected": [
                {
                    "vendor": "n/a",
                    "product": "n/a",
                    "versions": [
                        {
                            "version": "n/a",
                            "status": "affected"
                        }
                    ]
                }
            ],
            "references": [
                {
                    "url": "https://github.com/redis/redis-py/pull/2641"
                },
                {
                    "url": "https://github.com/redis/redis-py/issues/2665"
                }
            ],
            "problemTypes": [
                {
                    "descriptions": [
                        {
                            "type": "text",
                            "lang": "en",
                            "description": "n/a"
                        }
                    ]
                }
            ]
        }
    }
}